<mujoco>
<option timestep="0.005" gravity="0 0 -9.81"/>
<worldbody>
<light pos="0 0 3"/>
<geom name="floor" type="plane" size="5 5 .05" rgba=".8 .9 .8 1"/>
<body name="torso" pos="0 0 1.5">
<freejoint/>
<geom name="torso_geom" type="capsule" size="0.07 0.2" rgba=".2 .6 .8 1"/>
<body name="head" pos="0 0 .3">
<geom type="sphere" size=".1" rgba=".9 .2 .2 1"/>
</body>
<body name="arm" pos=".1 0 0">
<joint name="shoulder" type="hinge" axis="0 1 0"/>
<geom type="capsule" size="0.04 0.3" fromto="0 0 0 .3 0 0" rgba=".2 .8 .2 1"/>
</body>
</body>
</worldbody>
<actuator>
<motor joint="shoulder" ctrlrange="-100 100" ctrllimited="true"/>
</actuator>
</mujoco>